Workbook
Name _Order1: 255
Name _Order2: 0
Name asp두께: 0.15
Name layout: INDEX(#REF!,(MATCH(#REF!,#REF!)))
Name Layout_1: INDEX(#REF!,MATCH(#REF!,#REF!))
Name Macro2: #N/A
Name Macro4: #N/A
Name Macro5: #N/A
Name net: #N/A
Name NNNNN: #N/A
Name ㄴㄴㄴㄴㄴ: {"Book1","토공.xls"}
Name 다짐계수: 0.875
Name ㄹ호: [0]!ㄹ호
Name 레이아웃_테스트: INDEX(#REF!,(MATCH(#REF!,#REF!)))
Name 마구리: {"Book1","토공.xls"}
Name 배토판19ton: "Picture 11"
Name 배토판32ton: "Picture 10"
Name 보조기층두께: 0.2
Name 선택층두께: 0.2
Name 허허허허: {"Book1","토공.xls"}

Sheet 총괄수량(수리)
A1: HYDRAULIC PROFILE CALCULATION
A3: 1. 설계기준 : 1,000㎥/일
A4: 가. 설계기준수량 :
A5: 구 간 | E5: L.W.L (일평균) | F5: D.W.L (일최대) | G5: H.W.L (시간최대) | H5: 비 고
A7: 유입량 | B7: 생물반응조 | C7: 전체 | F7: 1041
F8: =ROUND((F7/86400),3) -> 0.012
C9: 지수 | D9: 2 | F9: =F7/$D$9 -> 520.5
F10: =ROUND((F9/86400),3) -> 0.006
A11: 유입량 | B11: 총인처리설비 | C11: 전체 | F11: 1042
F12: =ROUND((F11/86400),3) -> 0.012
C13: 지수 | D13: 2 | F13: =IF(D13=0,0,F11/$D$13) -> 521
F14: =ROUND((F13/86400),3) -> 0.006

Sheet 수리계산서
A1: 수리계산서
A3: 산출근거 | I3: L.W.L (일평균) | L3: D.W.L (일최대) | O3: H.W.L (시간최대)
A5: 생물반응조 유입유량(Q) | M5: ='총괄수량(수리)'!F7 -> 1041 | N5: ㎥/일
M6: ='총괄수량(수리)'!F8 -> 0.012 | N6: ㎥/sec
A7: 생물반응조 지당유량(q) | M7: ='총괄수량(수리)'!F10 -> 0.006 | N7: ㎥/sec
A9: 총인처리 설비 유입유량(Q) | M9: ='총괄수량(수리)'!F11 -> 1042 | N9: ㎥/일
M10: ='총괄수량(수리)'!F12 -> 0.012 | N10: ㎥/sec
A11: 부상분리설비 지당유량(q) | M11: ='총괄수량(수리)'!F14 -> 0.006 | N11: ㎥/sec
A13: 1. 부상분리 처리수조 수위(EL. m) | M13: 45.355 | N13: m
A14: 처리수조 ~ 부상분리설비 : Pumping
A16: 2. 부상분리조 수위(EL. m) | M16: =M13+M21 -> 46.678343 | N16: m
A17: - 유출 개구부 손실
B18: 개구부직경 (m) | F18: 0.125
B19: 개구부 면적(m2) | F19: =3.14*F18^2/4 -> 0.012265625
B20: 개구부 개소(개/지) | F20: 2
B21: 손실수두(m) △h = | M21: =M11/($F$23*$F$19*$F$20*(19.6^0.5))^2 -> 1.3233431 | N21: m
B22: △h = (Q/CA√2g)2
B23: C: 유량계수 | F23: 0.62
A25: 3. 부상분리조 유입 수위(EL. m) | M25: =M16+M31 -> 46.678405 | N25: m
A26: - 유출 개구부 손실
B27: 수문폭 (m) | F27: 3.6
B28: 수문높이 (m) | F28: 1
B29: 수문 개구부 면적(m2) | F29: =F27*F28 -> 3.6
B30: 수문 개구부 개소(개/지) | F30: 1
B31: 손실수두(m) △h = | M31: =M11/($F$33*$F$29*$F$30*(19.6^0.5))^2 -> 6.1447865e-05 | N31: m
B32: △h = (Q/CA√2g)2
B33: C: 유량계수 | F33: 0.62
A35: 4. 응집조 수위(EL. m) | M35: =F39+M40 -> 45.254362 | N35: m
B36: 유출 웨어길이 (m) | F36: 3.6
B37: 개소 | F37: 1
B38: 웨어 총 길이(m) | F38: =F36*F37 -> 3.6
B39: 유출 웨어정고 (EL. m) | F39: =42.1+3.145 -> 45.245
B40: 월류수위(m) △h = | M40: =(M11/1.84/$F$38)^(2/3) -> 0.0093616834 | N40: m
B41: △h = (q/1.84/B)(2/3)
A43: 5. 혼화조 수위(EL. m) | M43: =M35+M49 -> 45.257547 | N43: m
A44: - 유출 개구부 손실
B45: 수문폭 (m) | F45: 1
B46: 수문높이 (m) | F46: 0.5
B47: 수문 개구부 면적(m2) | F47: =F45*F46 -> 0.5
B48: 수문 개구부 개소(개/지) | F48: 1
...
